Exception on /uploaded [POST]
Traceback (most recent call last):
  File "/Users/sandeep/anaconda3/lib/python3.7/site-packages/flask/app.py", line 1817, in wsgi_app
    response = self.full_dispatch_request()
  File "/Users/sandeep/anaconda3/lib/python3.7/site-packages/flask/app.py", line 1477, in full_dispatch_request
    rv = self.handle_user_exception(e)
  File "/Users/sandeep/anaconda3/lib/python3.7/site-packages/flask/app.py", line 1381, in handle_user_exception
    reraise(exc_type, exc_value, tb)
  File "/Users/sandeep/anaconda3/lib/python3.7/site-packages/flask/_compat.py", line 33, in reraise
    raise value
  File "/Users/sandeep/anaconda3/lib/python3.7/site-packages/flask/app.py", line 1475, in full_dispatch_request
    rv = self.dispatch_request()
  File "/Users/sandeep/anaconda3/lib/python3.7/site-packages/flask/app.py", line 1461, in dispatch_request
    return self.view_functions[rule.endpoint](**req.view_args)
  File "/Users/sandeep/Sandeep/ML & DL/SmartDiet/app/views/main.py", line 35, in upload_file
    return render_template('uploaded.html', title='Success', predictions=preds_decoded, user_image=f.filename)
  File "/Users/sandeep/anaconda3/lib/python3.7/site-packages/flask/templating.py", line 127, in render_template
    return _render(ctx.app.jinja_env.get_or_select_template(template_name_or_list),
  File "/Users/sandeep/anaconda3/lib/python3.7/site-packages/jinja2/environment.py", line 869, in get_or_select_template
    return self.get_template(template_name_or_list, parent, globals)
  File "/Users/sandeep/anaconda3/lib/python3.7/site-packages/jinja2/environment.py", line 830, in get_template
    return self._load_template(name, self.make_globals(globals))
  File "/Users/sandeep/anaconda3/lib/python3.7/site-packages/jinja2/environment.py", line 804, in _load_template
    template = self.loader.load(self, name, globals)
  File "/Users/sandeep/anaconda3/lib/python3.7/site-packages/jinja2/loaders.py", line 125, in load
    code = environment.compile(source, name, filename)
  File "/Users/sandeep/anaconda3/lib/python3.7/site-packages/jinja2/environment.py", line 591, in compile
    self.handle_exception(exc_info, source_hint=source_hint)
  File "/Users/sandeep/anaconda3/lib/python3.7/site-packages/jinja2/environment.py", line 780, in handle_exception
    reraise(exc_type, exc_value, tb)
  File "/Users/sandeep/anaconda3/lib/python3.7/site-packages/jinja2/_compat.py", line 37, in reraise
    raise value.with_traceback(tb)
  File "/Users/sandeep/Sandeep/ML & DL/SmartDiet/app/templates/uploaded.html", line 192, in template
    {% endblock %}
  File "/Users/sandeep/anaconda3/lib/python3.7/site-packages/jinja2/environment.py", line 497, in _parse
    return Parser(self, source, name, encode_filename(filename)).parse()
  File "/Users/sandeep/anaconda3/lib/python3.7/site-packages/jinja2/parser.py", line 901, in parse
    result = nodes.Template(self.subparse(), lineno=1)
  File "/Users/sandeep/anaconda3/lib/python3.7/site-packages/jinja2/parser.py", line 883, in subparse
    rv = self.parse_statement()
  File "/Users/sandeep/anaconda3/lib/python3.7/site-packages/jinja2/parser.py", line 144, in parse_statement
    self.fail_unknown_tag(token.value, token.lineno)
  File "/Users/sandeep/anaconda3/lib/python3.7/site-packages/jinja2/parser.py", line 97, in fail_unknown_tag
    return self._fail_ut_eof(name, self._end_token_stack, lineno)
  File "/Users/sandeep/anaconda3/lib/python3.7/site-packages/jinja2/parser.py", line 90, in _fail_ut_eof
    self.fail(' '.join(message), lineno)
  File "/Users/sandeep/anaconda3/lib/python3.7/site-packages/jinja2/parser.py", line 59, in fail
    raise exc(msg, lineno, self.name, self.filename)
jinja2.exceptions.TemplateSyntaxError: Encountered unknown tag 'endblock'.
